
Run model on cuda
Traceback (most recent call last):
  File "runner.py", line 157, in <module>
    main(args)
  File "runner.py", line 33, in main
    agent = Agent(True, learning_rate, gamma, entropy_coef, critic_coef, no_of_workers, batch_size, env)
  File "/home/kidimerek/Documents/Studium/Thesis/agnostic_rl-main/src/agent.py", line 22, in __init__
    self.model = Model(device, self.num_actions, env).to(device)
  File "/home/kidimerek/Documents/Studium/Thesis/agnostic_rl-main/src/commons/model.py", line 15, in __init__
    torch.zeros(1, *env.observation_space.shape)).to(device).view(1, -1).size(1)
  File "/home/kidimerek/miniconda3/lib/python3.7/site-packages/torch/nn/modules/module.py", line 1110, in _call_impl
    return forward_call(*input, **kwargs)
  File "/home/kidimerek/miniconda3/lib/python3.7/site-packages/torch/nn/modules/container.py", line 141, in forward
    input = module(input)
  File "/home/kidimerek/miniconda3/lib/python3.7/site-packages/torch/nn/modules/module.py", line 1110, in _call_impl
    return forward_call(*input, **kwargs)
  File "/home/kidimerek/miniconda3/lib/python3.7/site-packages/torch/nn/modules/conv.py", line 447, in forward
    return self._conv_forward(input, self.weight, self.bias)
  File "/home/kidimerek/miniconda3/lib/python3.7/site-packages/torch/nn/modules/conv.py", line 444, in _conv_forward
    self.padding, self.dilation, self.groups)
RuntimeError: Given groups=1, weight of size [32, 3, 8, 8], expected input[1, 210, 160, 3] to have 3 channels, but got 210 channels instead